Workbook

Sheet REGLAS
A1: CATEGORIA CUENTAS MEDICAS | B1: GRUPO INDICADOR | C1: REPS A VALIDAR | D1: NORMA
A2: ALOJAMIENTO | B2: NA | C2: {=_xlfn.TEXTJOIN(",",TRUE,_xlfn._xlws.FILTER(CONSOLIDADO!U:U,CONSOLIDADO!V:V=REGLAS!B2,"NA"))} -> NA | D2: INDICADOR TIPO E NO APLICA A IPS | I2: MATERIAL DE OSTEOSINTESIS | L2: FINALIZADO
A3: AMBULANCIA AEREA | B3: NA | C3: {=_xlfn.TEXTJOIN(",",TRUE,_xlfn._xlws.FILTER(CONSOLIDADO!U:U,CONSOLIDADO!V:V=REGLAS!B3,"NA"))} -> NA | D3: INDICADOR TIPO E NO APLICA A IPS | I3: IPS CON RHB | L3: FINALIZADO
A4: AMBULANCIAS | B4: NA | C4: {=_xlfn.TEXTJOIN(",",TRUE,_xlfn._xlws.FILTER(CONSOLIDADO!U:U,CONSOLIDADO!V:V=REGLAS!B4,"NA"))} -> NA | D4: INDICADOR TIPO E NO APLICA A IPS | I4: TODOS LOS PROVEEDORES | L4: FINALIZADO
A5: ASEGURABILIDAD | B5: NA | C5: {=_xlfn.TEXTJOIN(",",TRUE,_xlfn._xlws.FILTER(CONSOLIDADO!U:U,CONSOLIDADO!V:V=REGLAS!B5,"NA"))} -> NA | D5: INDICADOR TIPO E NO APLICA A IPS | I5: IPS | L5: FINALIZADO
A6: AUDITORIA | B6: NA | C6: {=_xlfn.TEXTJOIN(",",TRUE,_xlfn._xlws.FILTER(CONSOLIDADO!U:U,CONSOLIDADO!V:V=REGLAS!B6,"NA"))} -> NA | D6: INDICADOR TIPO E NO APLICA A IPS | I6: IPS-RHI-RIESGO BIOLOGICO | L6: FINALIZADO
A7: AUDITORIA E INTERVENTORIA | B7: NA | C7: {=_xlfn.TEXTJOIN(",",TRUE,_xlfn._xlws.FILTER(CONSOLIDADO!U:U,CONSOLIDADO!V:V=REGLAS!B7,"NA"))} -> NA | D7: INDICADOR TIPO E NO APLICA A IPS | I7: RIESGO BIOLOGICO | L7: FINALIZADO
A8: COBERTURA INTERNACIONAL | B8: NA | C8: {=_xlfn.TEXTJOIN(",",TRUE,_xlfn._xlws.FILTER(CONSOLIDADO!U:U,CONSOLIDADO!V:V=REGLAS!B8,"NA"))} -> NA | D8: INDICADOR TIPO E NO APLICA A IPS | I8: ALIADO RHI | L8: FINALIZADO
A9: EPS | B9: IPS | C9: {=_xlfn.TEXTJOIN(",",TRUE,_xlfn._xlws.FILTER(CONSOLIDADO!U:U,CONSOLIDADO!V:V=REGLAS!B9,"NA"))} -> 328,334,329,302,316,330,333,344,355,372,308,327,332,339,301,340,363,387,310,321,323,331,336,348,345,377,311,326,338,343,347,411,335,303,317,366,367,383,362,354,410,218,309,412,413,414,415,416,417,422,369,393,395,406,235,324,407,304,745,745,1102,129,133,1102,129,129,129,131,1102,EAI01,744,1102,129,131,107,110,129,133,134,135,107,110,129,131,132,1102,201,202,203,205,207,208,209,210,211,213,214,215,218,231,233,234,235,245 | D9: INDICADOR TIPO E NO APLICA A IPS | I9: MEDICAMENTOS | L9: PENDIENTE AGOSTO
A10: ESPECIALISTA | B10: VALIDAR YEIMY | C10: {=_xlfn.TEXTJOIN(",",TRUE,_xlfn._xlws.FILTER(CONSOLIDADO!U:U,CONSOLIDADO!V:V=REGLAS!B10,"NA"))} -> NA | D10: INDICADOR TIPO E NO APLICA A IPS
A11: HERRAMIENTA DE GESTIÓN | B11: NA | C11: {=_xlfn.TEXTJOIN(",",TRUE,_xlfn._xlws.FILTER(CONSOLIDADO!U:U,CONSOLIDADO!V:V=REGLAS!B11,"NA"))} -> NA | D11: INDICADOR TIPO E NO APLICA A IPS
A12: HOSPEDAJE-TIQUETES | B12: NA | C12: {=_xlfn.TEXTJOIN(",",TRUE,_xlfn._xlws.FILTER(CONSOLIDADO!U:U,CONSOLIDADO!V:V=REGLAS!B12,"NA"))} -> NA | D12: INDICADOR TIPO E NO APLICA A IPS
A13: INTERVENTORIA | B13: NA | C13: {=_xlfn.TEXTJOIN(",",TRUE,_xlfn._xlws.FILTER(CONSOLIDADO!U:U,CONSOLIDADO!V:V=REGLAS!B13,"NA"))} -> NA | D13: INDICADOR TIPO E NO APLICA A IPS
A14: INVESTIGADOR | B14: VALIDAR YEIMY | C14: {=_xlfn.TEXTJOIN(",",TRUE,_xlfn._xlws.FILTER(CONSOLIDADO!U:U,CONSOLIDADO!V:V=REGLAS!B14,"NA"))} -> NA | D14: INDICADOR TIPO E NO APLICA A IPS | I14: REPS PARA MARCA PRESTADOR DE REHABILITACION
A15: IPS ATENCIÓN DOMICILIARIA | B15: IPS | C15: {=_xlfn.TEXTJOIN(",",TRUE,_xlfn._xlws.FILTER(CONSOLIDADO!U:U,CONSOLIDADO!V:V=REGLAS!B15,"NA"))} -> 328,334,329,302,316,330,333,344,355,372,308,327,332,339,301,340,363,387,310,321,323,331,336,348,345,377,311,326,338,343,347,411,335,303,317,366,367,383,362,354,410,218,309,412,413,414,415,416,417,422,369,393,395,406,235,324,407,304,745,745,1102,129,133,1102,129,129,129,131,1102,EAI01,744,1102,129,131,107,110,129,133,134,135,107,110,129,131,132,1102,201,202,203,205,207,208,209,210,211,213,214,215,218,231,233,234,235,245 | D15: INDICADOR TIPO E NO APLICA A IPS | I15: MEDICINA FISICA Y REHABILITACION - 327
A16: IPS ATENCIÓN DOMICILIARIA-LABORATORIO-IMAGENOLOGIA | B16: IPS | C16: {=_xlfn.TEXTJOIN(",",TRUE,_xlfn._xlws.FILTER(CONSOLIDADO!U:U,CONSOLIDADO!V:V=REGLAS!B16,"NA"))} -> 328,334,329,302,316,330,333,344,355,372,308,327,332,339,301,340,363,387,310,321,323,331,336,348,345,377,311,326,338,343,347,411,335,303,317,366,367,383,362,354,410,218,309,412,413,414,415,416,417,422,369,393,395,406,235,324,407,304,745,745,1102,129,133,1102,129,129,129,131,1102,EAI01,744,1102,129,131,107,110,129,133,134,135,107,110,129,131,132,1102,201,202,203,205,207,208,209,210,211,213,214,215,218,231,233,234,235,245 | D16: INDICADOR TIPO E NO APLICA A IPS | I16: MEDICINA DEL TRABAJO Y LABORAL - 407
A17: IPS SALUD MENTAL | B17: IPS | C17: {=_xlfn.TEXTJOIN(",",TRUE,_xlfn._xlws.FILTER(CONSOLIDADO!U:U,CONSOLIDADO!V:V=REGLAS!B17,"NA"))} -> 328,334,329,302,316,330,333,344,355,372,308,327,332,339,301,340,363,387,310,321,323,331,336,348,345,377,311,326,338,343,347,411,335,303,317,366,367,383,362,354,410,218,309,412,413,414,415,416,417,422,369,393,395,406,235,324,407,304,745,745,1102,129,133,1102,129,129,129,131,1102,EAI01,744,1102,129,131,107,110,129,133,134,135,107,110,129,131,132,1102,201,202,203,205,207,208,209,210,211,213,214,215,218,231,233,234,235,245 | D17: INDICADOR TIPO E NO APLICA A IPS | I17: FISIOTERAPIA - 739
A18: IPS-ALTA COMPLEJIDAD | B18: IPS | C18: {=_xlfn.TEXTJOIN(",",TRUE,_xlfn._xlws.FILTER(CONSOLIDADO!U:U,CONSOLIDADO!V:V=REGLAS!B18,"NA"))} -> 328,334,329,302,316,330,333,344,355,372,308,327,332,339,301,340,363,387,310,321,323,331,336,348,345,377,311,326,338,343,347,411,335,303,317,366,367,383,362,354,410,218,309,412,413,414,415,416,417,422,369,393,395,406,235,324,407,304,745,745,1102,129,133,1102,129,129,129,131,1102,EAI01,744,1102,129,131,107,110,129,133,134,135,107,110,129,131,132,1102,201,202,203,205,207,208,209,210,211,213,214,215,218,231,233,234,235,245 | D18: INDICADOR TIPO E NO APLICA A IPS | I18: TERAPIA OCUPACIONAL - 728
A19: IPS-BAJA COMPLEJIDAD | B19: IPS | C19: {=_xlfn.TEXTJOIN(",",TRUE,_xlfn._xlws.FILTER(CONSOLIDADO!U:U,CONSOLIDADO!V:V=REGLAS!B19,"NA"))} -> 328,334,329,302,316,330,333,344,355,372,308,327,332,339,301,340,363,387,310,321,323,331,336,348,345,377,311,326,338,343,347,411,335,303,317,366,367,383,362,354,410,218,309,412,413,414,415,416,417,422,369,393,395,406,235,324,407,304,745,745,1102,129,133,1102,129,129,129,131,1102,EAI01,744,1102,129,131,107,110,129,133,134,135,107,110,129,131,132,1102,201,202,203,205,207,208,209,210,211,213,214,215,218,231,233,234,235,245 | D19: INDICADOR TIPO E NO APLICA A IPS | I19: PSICOLOGIA - 344
A20: IPS-MEDIANA Y BAJA COMPLEJIDAD | B20: IPS | C20: {=_xlfn.TEXTJOIN(",",TRUE,_xlfn._xlws.FILTER(CONSOLIDADO!U:U,CONSOLIDADO!V:V=REGLAS!B20,"NA"))} -> 328,334,329,302,316,330,333,344,355,372,308,327,332,339,301,340,363,387,310,321,323,331,336,348,345,377,311,326,338,343,347,411,335,303,317,366,367,383,362,354,410,218,309,412,413,414,415,416,417,422,369,393,395,406,235,324,407,304,745,745,1102,129,133,1102,129,129,129,131,1102,EAI01,744,1102,129,131,107,110,129,133,134,135,107,110,129,131,132,1102,201,202,203,205,207,208,209,210,211,213,214,215,218,231,233,234,235,245 | D20: INDICADOR TIPO E NO APLICA A IPS
A21: LABORATORIO-IMAGENOLOGIA | B21: IPS | C21: {=_xlfn.TEXTJOIN(",",TRUE,_xlfn._xlws.FILTER(CONSOLIDADO!U:U,CONSOLIDADO!V:V=REGLAS!B21,"NA"))} -> 328,334,329,302,316,330,333,344,355,372,308,327,332,339,301,340,363,387,310,321,323,331,336,348,345,377,311,326,338,343,347,411,335,303,317,366,367,383,362,354,410,218,309,412,413,414,415,416,417,422,369,393,395,406,235,324,407,304,745,745,1102,129,133,1102,129,129,129,131,1102,EAI01,744,1102,129,131,107,110,129,133,134,135,107,110,129,131,132,1102,201,202,203,205,207,208,209,210,211,213,214,215,218,231,233,234,235,245 | D21: INDICADOR TIPO E NO APLICA A IPS
A22: LENTES | B22: VALIDAR YEIMY | C22: {=_xlfn.TEXTJOIN(",",TRUE,_xlfn._xlws.FILTER(CONSOLIDADO!U:U,CONSOLIDADO!V:V=REGLAS!B22,"NA"))} -> NA | D22: INDICADOR TIPO E NO APLICA A IPS
A23: MATERIAL DE OSTEOSINTESIS | B23: MATERIAL DE OSTEOSINTESIS | C23: {=_xlfn.TEXTJOIN(",",TRUE,_xlfn._xlws.FILTER(CONSOLIDADO!U:U,CONSOLIDADO!V:V=REGLAS!B23,"NA"))} -> AHT07,CMO08,OEM06,AAM09 | D23: INDICADOR TIPO E NO APLICA A IPS
A24: MEDICAMENTOS | B24: MEDICAMENTOS | C24: {=_xlfn.TEXTJOIN(",",TRUE,_xlfn._xlws.FILTER(CONSOLIDADO!U:U,CONSOLIDADO!V:V=REGLAS!B24,"NA"))} -> NA | D24: INDICADOR TIPO E NO APLICA A IPS
A25: MEDICINA LABORAL | B25: IPS | C25: {=_xlfn.TEXTJOIN(",",TRUE,_xlfn._xlws.FILTER(CONSOLIDADO!U:U,CONSOLIDADO!V:V=REGLAS!B25,"NA"))} -> 328,334,329,302,316,330,333,344,355,372,308,327,332,339,301,340,363,387,310,321,323,331,336,348,345,377,311,326,338,343,347,411,335,303,317,366,367,383,362,354,410,218,309,412,413,414,415,416,417,422,369,393,395,406,235,324,407,304,745,745,1102,129,133,1102,129,129,129,131,1102,EAI01,744,1102,129,131,107,110,129,133,134,135,107,110,129,131,132,1102,201,202,203,205,207,208,209,210,211,213,214,215,218,231,233,234,235,245 | D25: INDICADOR TIPO E NO APLICA A IPS
A26: ODONTOLOGIA | B26: IPS | C26: {=_xlfn.TEXTJOIN(",",TRUE,_xlfn._xlws.FILTER(CONSOLIDADO!U:U,CONSOLIDADO!V:V=REGLAS!B26,"NA"))} -> 328,334,329,302,316,330,333,344,355,372,308,327,332,339,301,340,363,387,310,321,323,331,336,348,345,377,311,326,338,343,347,411,335,303,317,366,367,383,362,354,410,218,309,412,413,414,415,416,417,422,369,393,395,406,235,324,407,304,745,745,1102,129,133,1102,129,129,129,131,1102,EAI01,744,1102,129,131,107,110,129,133,134,135,107,110,129,131,132,1102,201,202,203,205,207,208,209,210,211,213,214,215,218,231,233,234,235,245 | D26: INDICADOR TIPO E NO APLICA A IPS
A27: OPERACIÓN LOGISTICA | B27: VALIDAR YEIMY | C27: {=_xlfn.TEXTJOIN(",",TRUE,_xlfn._xlws.FILTER(CONSOLIDADO!U:U,CONSOLIDADO!V:V=REGLAS!B27,"NA"))} -> NA | D27: INDICADOR TIPO E NO APLICA A IPS
A28: ORTESIS-PROTESIS | B28: VALIDAR YEIMY | C28: {=_xlfn.TEXTJOIN(",",TRUE,_xlfn._xlws.FILTER(CONSOLIDADO!U:U,CONSOLIDADO!V:V=REGLAS!B28,"NA"))} -> NA | D28: INDICADOR TIPO E NO APLICA A IPS
A29: OTRO | B29: NA | C29: {=_xlfn.TEXTJOIN(",",TRUE,_xlfn._xlws.FILTER(CONSOLIDADO!U:U,CONSOLIDADO!V:V=REGLAS!B29,"NA"))} -> NA | D29: INDICADOR TIPO E NO APLICA A IPS
A30: REHABILITACIÓN | B30: ALIADO RHI | C30: {=_xlfn.TEXTJOIN(",",TRUE,_xlfn._xlws.FILTER(CONSOLIDADO!U:U,CONSOLIDADO!V:V=REGLAS!B30,"NA"))} -> POR DEFINIR ,POR DEFINIR ,POR DEFINIR ,POR DEFINIR | D30: INDICADOR TIPO E NO APLICA A IPS
A31: REHABILITACIÓN-IPS ATENCIÓN DOMICILIARIA | B31: ALIADO RHI | C31: {=_xlfn.TEXTJOIN(",",TRUE,_xlfn._xlws.FILTER(CONSOLIDADO!U:U,CONSOLIDADO!V:V=REGLAS!B31,"NA"))} -> POR DEFINIR ,POR DEFINIR ,POR DEFINIR ,POR DEFINIR | D31: INDICADOR TIPO E NO APLICA A IPS
A32: SUMINISTRO MEDICAMENTOS-OXIGENO | C32: {=_xlfn.TEXTJOIN(",",TRUE,_xlfn._xlws.FILTER(CONSOLIDADO!U:U,CONSOLIDADO!V:V=REGLAS!B32,"NA"))} | D32: INDICADOR TIPO E NO APLICA A IPS
A33: TRANSPORTE NO URGENTES | B33: NA | C33: {=_xlfn.TEXTJOIN(",",TRUE,_xlfn._xlws.FILTER(CONSOLIDADO!U:U,CONSOLIDADO!V:V=REGLAS!B33,"NA"))} -> NA | D33: INDICADOR TIPO E NO APLICA A IPS

Sheet CONSOLIDADO
A1: TIPO INDICADOR | B1: CATEGORÍA | C1: NOMBRE DEL INDICADOR | D1: FECHA DE CREACIÓN DEL INDICADOR | E1: CÓDIGO Res. 256 de 2016 | F1: CÓDIGO PROPIO | G1: DESCRIPCIÓN | H1: FORMULA | I1: NUMERADOR | J1: FUENTE DEL NUMERADOR | K1: DENOMINADOR | L1: FUENTE DEL DENOMINADOR | M1: UNIDAD DE MEDIDA | N1: META | O1: PERIODICIDAD | P1: PROGRESIVIDAD | Q1: OBSERVACIONES | R1: METODOLOGÍA | S1: EXCLUSIONES | T1: RESPONSABLE | U1: CÓDIGO REPS | V1: TIPO DE PROVEEDOR | W1: LLAVE | X1: CONDICION
A2: Gestión | B2: Adherencia | C2: Adherencia a la herramienta Tecnológica designada por la compañía | D2: Apartir de suscripcion del acuerdo del indicador con el prestador | E2: N/A | F2: I.C.119 | G2: Medir la gestion oportuna del proveedor en las herramientas tecnologicas designadas por la compañía, frente a los servicios autorizados. | H2: Número de cargues completos en bitácora * 100 / Número total de autorizaciones asginadas | I2: Número de cargues completos en bitácora * 100 | J2: Bitácoras de la herramienta tecnológica de la compañía | K2: Número total de autorizaciones asginadas | L2: Bitácoras de la herramienta tecnológica de la compañía | M2: Porcentaje | N2: 0.98 | O2: Mensual | P2: Ascendente | Q2: El registro en la bitácora de la herramienta tecnológica de la compañía, contará con la siguiente información (compromiso de entrega, novedades, entrega efectiva): Compromiso de entrega: paciente – fecha – hora de cirugía – fecha – hora de entrega – material – persona de contacto en la IPS. (Registro en bitácora máximo 2 días hábiles) Novedades: paciente- IPS -descripción del evento – notificación del evento IPS, ente autorizador (nombre-fecha-hora), requiere soporte técnico (nombre-fecha-hora). (Registro en bitácora máximo 2 días hábiles) Entrega efectiva: fecha - hora de entrega –material entregado- persona que recibe en la IPS (Registro en bitácora máximo 4 días hábiles). *En las autorizaciones vencidas debe quedar la nota de escalamiento a la operación para renovar la autorización. * En autorizaciones anuladas por causa del proveedor debe quedar la nota de la causa por parte del prestador para no dar cumplimiento al servicio. * El proveedor deberá registrar en la bitácora del aplicativo tecnologico de la compañía el compromiso de entrega, novedades y entrega efectiva de cada uno de los suministros autorizados. | R2: Muestra: Se realizara la validacion del 100% de la autorizaciones asignadas en el periodo a evaluar. Metodología denominador: 1.Se revisará en la herramienta tecnologíca todas las autorizaciones asignadas al proveedor. 2.Se excluiran de la medicion las autorizaciones que cumplan con los criterios definidos como exclusión. Metodología numerador: 1. Se revisará en la herramienta tecnologíca que todas las autorizaciones cuenten con lo definido en el indicador(Observaciones) segun aplique. | S2: • Falla en la herramienta de gestión establecida por la compañía • Autorización anulada siempre y cuando no sea por una causa atribuible al proveedor • Pendiente programación de cirugía. | T2: Supervisor y/o interventoria designada. | U2: AHT07 | V2: MATERIAL DE OSTEOSINTESIS | W2: POR TIPO | X2: MATERIAL DE OSTEOSINTESIS
A3: Gestión | B3: Oportunidad | C3: Oportunidad en la asignación de cita de terapias | D3: Apartir de suscripcion del acuerdo del indicador con el prestador | E3: N/A | F3: I.C.136 | G3: Expresa el tiempo de espera en dias calendario que transcurren entre la fecha de solicitud de la cita para terapias y la fecha en la cual el usuario la solicitó | H3: Sumatoria de la diferencia de los dias calendario entre la fecha en la que se asignó la cita de terapias y la fecha en la cual el usuario la solicitó / número total de citas de terpias asignadas | I3: Sumatoria de la diferencia de los dias calendario entre la fecha en la que se asignó la cita de terapias | J3: Sistema de Gestión de Calidad de la Institución | K3: número total de citas de terpias asignadas | L3: Sistema de Gestión de Calidad de la Institución | M3: Días | N3: 2 días | O3: Trimestral | P3: Descendente | Q3: Ninguna | R3: La firma de interventoria o supervisor solicita a los proveedores de prestaciones de servicios de salud con los cuales se tiene contrato vigente, el reporte de los datos reelacionados con este indicador respecto a los asegurados de Positiva que registran atenciones de este servicio en el periodo evaluado. | S3: Ninguna | T3: Supervisor y/o interventoria designada. | U3: 418 | V3: IPS CON RHB | W3: 418 | X3: REPS HABILITADO
A4: Gestión | B4: Oportunidad | C4: Oportunidad en la asignación de cita de terapias | D4: Apartir de suscripcion del acuerdo del indicador con el prestador | E4: N/A | F4: I.C.136 | G4: Expresa el tiempo de espera en dias calendario que transcurren entre la fecha de solicitud de la cita para terapias y la fecha en la cual el usuario la solicitó | H4: Sumatoria de la diferencia de los dias calendario entre la fecha en la que se asignó la cita de terapias y la fecha en la cual el usuario la solicitó / número total de citas de terpias asignadas | I4: Sumatoria de la diferencia de los dias calendario entre la fecha en la que se asignó la cita de terapias | J4: Sistema de Gestión de Calidad de la Institución | K4: número total de citas de terpias asignadas | L4: Sistema de Gestión de Calidad de la Institución | M4: Días | N4: 2 días | O4: Trimestral | P4: Descendente | Q4: Ninguna | R4: La firma de interventoria o supervisor solicita a los proveedores de prestaciones de servicios de salud con los cuales se tiene contrato vigente, el reporte de los datos reelacionados con este indicador respecto a los asegurados de Positiva que registran atenciones de este servicio en el periodo evaluado. | S4: Ninguna | T4: Supervisor y/o interventoria designada. | U4: 417 | V4: IPS CON RHB | W4: 417 | X4: REPS HABILITADO
A5: Gestión | B5: Oportunidad | C5: Oportunidad en la asignación de cita de terapias | D5: Apartir de suscripcion del acuerdo del indicador con el prestador | E5: N/A | F5: I.C.137 | G5: Expresa el tiempo de espera en dias calendario que transcurren entre la fecha de solicitud de la cita para terapias y la fecha en la cual el usuario la solicitó | H5: Sumatoria de la diferencia de los dias calendario entre la fecha en la que se asignó la cita de terapias y la fecha en la cual el usuario la solicitó / número total de citas de terpias asignadas | I5: Sumatoria de la diferencia de los dias calendario entre la fecha en la que se asignó la cita de terapias | J5: Sistema de Gestión de Calidad de la Institución | K5: número total de citas de terpias asignadas | L5: Sistema de Gestión de Calidad de la Institución | M5: Días | N5: 2 días | O5: Trimestral | P5: Descendente | Q5: Ninguna | R5: La firma de interventoria o supervisor solicita a los proveedores de prestaciones de servicios de salud con los cuales se tiene contrato vigente, el reporte de los datos reelacionados con este indicador respecto a los asegurados de Positiva que registran atenciones de este servicio en el periodo evaluado. | S5: Ninguna | T5: Supervisor y/o interventoria designada. | U5: 419 | V5: IPS CON RHB | W5: 419 | X5: REPS HABILITADO
A6: Gestión | B6: Oportunidad | C6: Oportunidad en la asignación de cita de terapias | D6: Apartir de suscripcion del acuerdo del indicador con el prestador | E6: N/A | F6: I.C.138 | G6: Expresa el tiempo de espera en dias calendario que transcurren entre la fecha de solicitud de la cita para terapias y la fecha en la cual el usuario la solicitó | H6: Sumatoria de la diferencia de los dias calendario entre la fecha en la que se asignó la cita de terapias y la fecha en la cual el usuario la solicitó / número total de citas de terpias asignadas | I6: Sumatoria de la diferencia de los dias calendario entre la fecha en la que se asignó la cita de terapias | J6: Sistema de Gestión de Calidad de la Institución | K6: número total de citas de terpias asignadas | L6: Sistema de Gestión de Calidad de la Institución | M6: Días | N6: 2 días | O6: Trimestral | P6: Descendente | Q6: Ninguna | R6: La firma de interventoria o supervisor solicita a los proveedores de prestaciones de servicios de salud con los cuales se tiene contrato vigente, el reporte de los datos reelacionados con este indicador respecto a los asegurados de Positiva que registran atenciones de este servicio en el periodo evaluado. | S6: Ninguna | T6: Supervisor y/o interventoria designada. | U6: 728 | V6: IPS CON RHB | W6: 728 | X6: REPS HABILITADO
A7: Gestión | B7: Oportunidad | C7: Oportunidad en la asignación de cita de terapias | D7: Apartir de suscripcion del acuerdo del indicador con el prestador | E7: N/A | F7: I.C.139 | G7: Expresa el tiempo de espera en dias calendario que transcurren entre la fecha de solicitud de la cita para terapias y la fecha en la cual el usuario la solicitó | H7: Sumatoria de la diferencia de los dias calendario entre la fecha en la que se asignó la cita de terapias y la fecha en la cual el usuario la solicitó / número total de citas de terpias asignadas | I7: Sumatoria de la diferencia de los dias calendario entre la fecha en la que se asignó la cita de terapias | J7: Sistema de Gestión de Calidad de la Institución | K7: número total de citas de terpias asignadas | L7: Sistema de Gestión de Calidad de la Institución | M7: Días | N7: 1 días | O7: Trimestral | P7: Descendente | Q7: Ninguna | R7: La firma de interventoria o supervisor solicita a los proveedores de prestaciones de servicios de salud con los cuales se tiene contrato vigente, el reporte de los datos reelacionados con este indicador respecto a los asegurados de Positiva que registran atenciones de este servicio en el periodo evaluado. | S7: Ninguna | T7: Supervisor y/o interventoria designada. | U7: 729 | V7: IPS CON RHB | W7: 729 | X7: REPS HABILITADO
A8: Gestión | B8: Oportunidad | C8: Oportunidad en la asignación de cita de terapias | D8: Apartir de suscripcion del acuerdo del indicador con el prestador | E8: N/A | F8: I.C.145 | G8: Expresa el tiempo de espera en dias calendario que transcurren entre la fecha de solicitud de la cita para terapias y la fecha en la cual el usuario la solicitó | H8: Sumatoria de la diferencia de los dias calendario entre la fecha en la que se asignó la cita de terapias y la fecha en la cual el usuario la solicitó / número total de citas de terpias asignadas | I8: Sumatoria de la diferencia de los dias calendario entre la fecha en la que se asignó la cita de terapias | J8: Sistema de Gestión de Calidad de la Institución | K8: número total de citas de terpias asignadas | L8: Sistema de Gestión de Calidad de la Institución | M8: Días | N8: 1 días | O8: Trimestral | P8: Descendente | Q8: Ninguna | R8: La firma de interventoria o supervisor solicita a los proveedores de prestaciones de servicios de salud con los cuales se tiene contrato vigente, el reporte de los datos reelacionados con este indicador respecto a los asegurados de Positiva que registran atenciones de este servicio en el periodo evaluado. | S8: Ninguna | T8: Supervisor y/o interventoria designada. | U8: OAD24 | V8: IPS CON RHB | W8: POR TIPO
A9: Calidad | B9: Calidad | C9: Calidad del material de osteosíntesis | D9: Apartir de suscripcion del acuerdo del indicador con el prestador | E9: N/A | F9: I.C.120 | G9: Medir la calidad calidad del material de osteosíntesis suministrado por el proveedor para los asegurados de la compañía. | H9: Número de reintervenciones asociadas a fatiga o fallas de calidad del material de osteosíntesis (extracciones de dispositivos relacionados con ruptura, cambios en el diseño no notificados al cliente, fallas o falencias en las materias primas del dispositivo) | I9: Número de reintervenciones asociadas a fatiga o fallas de calidad del material de osteosíntesis (extracciones de dispositivos relacionados con ruptura, cambios en el diseño no notificados al cliente, fallas o falencias en las materias primas del dispositivo) | J9: Base de datos de autorizaciones del aplicativo Cuida 2.0, extraciones, bitacoras Cuida II, Sistemas de informacion del proveedor, encuestas medicos tratantes, analisis de caso, INVIMA, reportes de calidad o de producción originadora y demás elementos que permitan la identificacion de casos reintervenciones. | K9: NA | L9: NA | M9: Número de reintervenciones asociadas a fatiga o fallas de calidad del material de osteosíntesis | N9: 0 | O9: Trimestral | P9: Descendente | Q9: *Las reintervenciones: extracciones de dispositivos relacionados con ruptura, cambios en el diseño no notificados al cliente, fallas o falencias en las materias primas del dispositivo. *En caso que se presente posible falla del material o fractura del mismo, se debe garantizar el envío del material fracturado a la respectiva casa fabricante para que se le realice la trazabilidad de acuerdo al lote de fabricación que tiene cada pieza de material y así se genere un informe de total confianza para POSITIVA ARL y poder definir si el evento ocurrido tiene o no que ver con la calidad de fabricación. | R9: * Con base en la información recolectada validara la existencia de reintervenciones en el periodo. * Se notificara y requerira al proveedor informacion relacionada con las reintervenciones identificadas, allegando la información necesaria de los casos. *El proveedor tiene un plazo de 10 días hábiles para demostrar que la falla no es atribuible a la calidad del producto. * De acuerdo con los resultados se aplicara la formula del indicador. | S9: Ninguna | T9: Supervisor y/o interventoria designada. | U9: CMO08 | V9: MATERIAL DE OSTEOSINTESIS | W9: POR TIPO | X9: MATERIAL DE OSTEOSINTESIS
A10: Gestión | B10: Gestión | C10: Oportunidad En La Radicación De Facturas Por Proveedor | D10: Apartir de suscripcion del acuerdo del indicador con el prestador | E10: N/A | F10: I.C.110 | G10: El indicador busca monitorear los días que se demora el prestador de servicios o tecnologias de salud IPS o proveedor en facturar el servicio prestado. | H10: Promedio ( aritmético) de número de dias resultado (Fecha de radicación de la factura menos (-) fecha de prestación del servicio u homologa) | I10: Promedio ( aritmético) de número de dias resultado (Fecha de radicación de la factura menos) | J10: Herramienta Tecnológica Vigente Definida Por Positiva | K10: fecha de prestación del servicio u homologa | L10: Herramienta Tecnológica Vigente Definida Por Positiva | M10: Número promedio ( aritmético) de dias | N10: 30 días calendario | O10: Trimestral o mensual dependiendo de la periodicidad del informe de interventoria a reportar | P10: Descendente | Q10: Realizada Por Parte Del Del Servicio De Interventoría | R10: La firma interventora accede al aplicativo dispuesto por la compañia que registra (reporte de radicaciòn para conocer la fecha del servicio y la fecha de radicación de cada una de las facturas registradas ante Positiva), de acuerdo a la vigencia del contrato. | S10: Fallas en la operación por parte del proveedor de radicación / inconsistencias en la herramienta tecnológica de radicación. Si no hay radicación para el periodo a medir se debe colocar No aplica - sin radicación. | T10: Supervisor y/o interventoria designada. | U10: Todos los REPS | V10: TODOS LOS PROVEEDORES | W10: ALL | X10: TODOS
A11: Gestión | B11: Gestión | C11: Oportunidad En La Gestion De Las Devoluciones | D11: Apartir de suscripcion del acuerdo del indicador con el prestador | E11: N/A | F11: I.C.111 | G11: El indicador busca monitorear el número de devoluciones de facturas en radicación realizadas al proveedor. | H11: (Número total de facturas devueltas /( sobre) Número total de facturas radicadas en el periodo a evaluar) * (por) 100% | I11: Número total de facturas devueltas | J11: Herramienta Tecnológica Vigente Definida Por Positiva | K11: Número total de facturas radicadas en el periodo a evaluar) * (por) 100% | L11: Herramienta Tecnológica Vigente Definida Por Positiva | M11: Porcentaje de devoluciones | N11: Del 0 % al 5 % | O11: Trimestral o mensual dependiendo de la periodicidad del informe de interventoria a reportar | P11: Descendente | Q11: Realizada Por Parte Del Del Servicio De Interventoría | R11: La firma interventora accede al aplicativo que comprende la información de radicación para conocer el número de facturas devueltas debido a causa del proveedor | S11: Fallas tecnológicas o devolución errada por parte del operador de radicación. No aplica -sin devoluciones | T11: Supervisor y/o interventoria designada. | U11: Todos los REPS | V11: TODOS LOS PROVEEDORES | W11: ALL | X11: TODOS
A12: Gestión | B12: Gestión | C12: Oportunidad En La Respuesta De Glosas Por Proveedores | D12: Apartir de suscripcion del acuerdo del indicador con el prestador | E12: N/A | F12: I.C.112 | G12: El indicador busca monitorear los días que se demora el proveedor en responder a la glosa formulada por parte de la firma auditora. | H12: Promedio ( aritmético) del número de dias (Fecha de respuesta por parte del proveedor menos (-) menos Fecha de notificación de glosa ) | I12: Promedio ( aritmético) del número de dias (Fecha de respuesta por parte del proveedor menos | J12: Herramienta Tecnológica Vigente Definida Por Positiva | K12: Fecha de notificación de glosa | L12: Herramienta Tecnológica Vigente Definida Por Positiva | M12: Promedio ( aritmético) de número de dias que toma el proveedor para responder glosa. | N12: 20 días hábiles | O12: Trimestral o mensual dependiendo de la periodicidad del informe de interventoria a reportar | P12: Descendente | Q12: Realizada Por Parte Del Del Servicio De Interventoría | R12: La firma interventora accede al aplicativo que registra la información de auditoria, para conocer la fecha de notificación de la glosa y la fecha de la primera respuesta a la glosa por parte del proveedor. | S12: Inconsistencias en la herramienta tecnológica de auditoría. No aplica -sin glosa. Para los casos que al momento de la mediciòn del indicador no cuenta con respuesta estando en los terminos de ley se tomará como esta (fecha de primera respuesta) el día que se realiza la medición del indicador. | T12: Supervisor y/o interventoria designada. | U12: Todos los REPS | V12: TODOS LOS PROVEEDORES | W12: ALL | X12: TODOS
A13: Gestión | B13: Gestión | C13: Calidad En La Respuesta De Glosa Dadas Por El Proveedor | D13: Apartir de suscripcion del acuerdo del indicador con el prestador | E13: N/A | F13: I.C.113 | G13: El indicador busca monitorear las veces en que se realiza reunión de conciliación para validar con el proveedor la calidad de las respuestas dadas a las glosas formuladas. | H13: Suma del número de conciliaciones (reuniones) realizadas en el periodo a evaluar | I13: Suma del número de conciliaciones (reuniones) realizadas en el periodo a evaluar | J13: Informe De conciliación Cuentas Medicas | K13: N/A | L13: N/A | M13: Número de reuniones de conciliación | N13: 0 a 2 reuniones | O13: Trimestral o mensual dependiendo de la periodicidad del informe de interventoria a reportar | P13: Descendente | Q13: Realizada Por Parte Del Del Servicio De Interventoría | R13: La interventoría cuantificará de acuerdo a la información recibida del equipo de conciliación en número de veces en que se reunen con el proveedor para validar la calidad de las respuestas dadas a las glosas formuladas. | S13: No aplica -sin conciliaciòn. Para los casos que al momento de la mediciòn del indicador no cuenta con glosa generada | T13: Supervisor y/o interventoria designada. | U13: Todos los REPS | V13: TODOS LOS PROVEEDORES | W13: ALL | X13: TODOS
A14: calidad | B14: Oportunidad | C14: Tiempo promedio de espera para la asignación de cita de Medicina General | D14: Apartir de suscripcion del acuerdo del indicador con el prestador | E14: P.3.1 | F14: I.C.48 | G14: Expresa el tiempo de espera en días calendario que transcurren entre la fecha de solicitud de la cita para la consulta de Medicina general de primera vez por parte del paciente/ usuario a la IPS y la fecha en que es asignada | H14: Sumatoria de la diferencia de días calendario entre la fecha en la que se asignó la cita de Medicina general de primera vez y la fecha en la cual el usuario la solicitó/Número total de citas de Medicina General de primera vez asignadas | I14: Sumatoria de la diferencia de días calendario entre la fecha en la que se asignó la cita de Medicina general de primera vez y la fecha en la cual el usuario la solicitó | J14: Reporte remitido por los prestadores de servicios de acuerdo a lo establecido por la Resolución 256 de 2016 | K14: Número total de citas de Medicina General de primera vez asignadas | L14: Reporte remitido por los prestadores de servicios de acuerdo a lo establecido por la Resolución 256 de 2016 | M14: Días | N14: 4 días calendario | O14: Trimestral | P14: Descendente | Q14: La consulta de primera vez, hace referencia a la primera consulta del paciente que se registra por primera vez en el año razón por la cual se excluye la consulta de control. Aplica para IPS y no aplica para servicios de transporte especial de pacientes | R14: La firma de interventoria o supervisor solicita a los proveedores de prestaciones de servicios de salud con los cuales se tiene contrato vigente, el reporte de los datos reelacionados con este indicador respecto a los asegurados de Positiva que registran atenciones de este servicio en el periodo evaluado. | S14: Ninguna | T14: Supervisor y/o interventoria designada. | U14: 328 | V14: IPS | W14: 328 | X14: REPS HABILITADO
A15: calidad | B15: Oportunidad | C15: Tiempo promedio de espera para la asignación de cita de Odontologia general | D15: Apartir de suscripcion del acuerdo del indicador con el prestador | E15: P.3.2 | F15: I.C.49 | G15: Expresa el tiempo de espera en dias calendario que transcurren entre la fecha de la solicitud y la cita para consulta por Odontologia General de primera vez por parte del paciente/ usuario a la IPS y la fecha en que es asignada | H15: Sumatoria de la diferencia de días calendario entre la fecha en la que se asignó la cita de Odontología general de primera vez y la fecha en la cual el usuario la solicitó/Número total de citas de Odontología General de primera vez asignadas | I15: Sumatoria de la diferencia de días calendario entre la fecha en la que se asignó la cita de Odontología general de primera vez y la fecha en la cual el usuario la solicitó | J15: Reporte remitido por los prestadores de servicios de acuerdo a lo establecido por la Resolución 256 de 2016 | K15: Número total de citas de Odontología General de primera vez asignadas | L15: Reporte remitido por los prestadores de servicios de acuerdo a lo establecido por la Resolución 256 de 2016 | M15: Días | N15: 5 días calendario | O15: Trimestral | P15: Descendente | Q15: La consulta de primera vez hace referencia a la primera consulta del paciente que se registra por primera vez en el año, razón por la cual se excluye la consulta de control. Aplica para IPS y no aplica para los servicios de transporte especial de pacientes | R15: La firma de interventoria o supervisor solicita a los proveedores de prestaciones de servicios de salud con los cuales se tiene contrato vigente, el reporte de los datos reelacionados con este indicador respecto a los asegurados de Positiva que registran atenciones de este servicio en el periodo evaluado. | S15: Ninguna | T15: Supervisor y/o interventoria designada. | U15: 334 | V15: IPS | W15: 334 | X15: REPS HABILITADO
A16: calidad | B16: Oportunidad | C16: Tiempo promedio de espera para la asignación de cita de Medicina interna | D16: Apartir de suscripcion del acuerdo del indicador con el prestador | E16: P.3.3 | F16: I.C.50 | G16: Expresa el tiempo de espera en dias calendario que transcurren entre la fecha de solicitud de la cita para la consulta por Medicina Interna de primera vez y la fecha en la cual el usuario lo solicitó | H16: Sumatoria de la diferencia de los dias calendario entre la fecha en la que se asignó la cita de Medicina Interna de primera vez y la fecha en la cual el usuario la solicitó / número total de citas de medicina interna de primera vez asignadas | I16: Sumatoria de la diferencia de dias calendario entre la fecha en la que se asignó la cita de medicina interna de primera vez y la fecha en la cual el usuario la solicitó | J16: Reporte remitido por los prestadores de servicios de acuerdo a lo establecido por la Resolución 256 de 2016 | K16: Número total de citas de medicina interna de primera vez asignadas | L16: Reporte remitido por los prestadores de servicios de acuerdo a lo establecido por la Resolución 256 de 2016 | M16: Días | N16: 14 días calendario | O16: Trimestral | P16: Descendente | Q16: La consulta de primera vez hace referencia a la primera consulta del paciente que se registra por primera vez en el año, razón por la cual se excluye la consulta de control. Aplica para IPS y no aplica para los servicios de transporte especial de pacientes | R16: La firma de interventoria o supervisor solicita a los proveedores de prestaciones de servicios de salud con los cuales se tiene contrato vigente, el reporte de los datos reelacionados con este indicador respecto a los asegurados de Positiva que registran atenciones de este servicio en el periodo evaluado. | S16: Ninguna | T16: Supervisor y/o interventoria designada. | U16: 329 | V16: IPS | W16: 329 | X16: REPS HABILITADO
A17: calidad | B17: Oportunidad | C17: Tiempo promedio de espera para la asignación de cita de Cardiologia | D17: Apartir de suscripcion del acuerdo del indicador con el prestador | E17: N/A | F17: I.C.51 | G17: Expresa el tiempo de espera en dias calendario que transcurren entre la fecha de solicitud de la cita para la consulta por Cardiología de primera vez y la fecha en la cual el usuario la solicitó | H17: Sumatoria de la diferencia de los dias calendario entre la fecha en la que se asignó la cita de Cardiología de primera vez y la fecha en la cual el usuario la solicitó / número total de citas de cardiología de primera vez asignadas | I17: Sumatoria de la diferencia de dias calendario entre la fecha en la que se asignó la cita de cardiología de primera vez y la fecha en la cual el usuario la solicitó | J17: Sistema de Gestión de Calidad de la Institución | K17: Número total de citas de cardiología de primera vez asignadas | L17: Sistema de Gestión de Calidad de la Institución | M17: Días | N17: 5 días calendario | O17: Trimestral | P17: Descendente | Q17: La consulta de primera vez hace referencia a la primera consulta del paciente que se registra por primera vez en el año, razón por la cual se excluye la consulta de control. Aplica para IPS y no aplica para los servicios de transporte especial de pacientes | R17: La firma de interventoria o supervisor solicita a los proveedores de prestaciones de servicios de salud con los cuales se tiene contrato vigente, el reporte de los datos reelacionados con este indicador respecto a los asegurados de Positiva que registran atenciones de este servicio en el periodo evaluado. | S17: Ninguna | T17: Supervisor y/o interventoria designada. | U17: 302 | V17: IPS | W17: 302 | X17: REPS HABILITADO
A18: calidad | B18: Oportunidad | C18: Tiempo promedio de espera para la asignación de cita de Gastroenterología | D18: Apartir de suscripcion del acuerdo del indicador con el prestador | E18: N/A | F18: I.C.52 | G18: Expresa el tiempo de espera en dias calendario que transcurren entre la fecha de solicitud de la cita para la consulta por Gastroenterología de primera vez y la fecha en la cual el usuario la solicitó | H18: Sumatoria de la diferencia de los dias calendario entre la fecha en la que se asignó la cita de Gastroenterología de primera vez y la fecha en la cual el usuario la solicitó / número total de citas de gastroenterología de primera vez asignadas | I18: Sumatoria de la diferencia de dias calendario entre la fecha en la que se asignó la cita de gastroenterología de primera vez y la fecha en la cual el usuario la solicitó | J18: Sistema de Gestión de Calidad de la Institución | K18: Número total de citas de gastroenterología de primera vez asignadas | L18: Sistema de Gestión de Calidad de la Institución | M18: Días | N18: 5 días calendario | O18: Trimestral | P18: Descendente | Q18: La consulta de primera vez hace referencia a la primera consulta del paciente que se registra por primera vez en el año, razón por la cual se excluye la consulta de control. Aplica para IPS y no aplica para los servicios de transporte especial de pacientes | R18: La firma de interventoria o supervisor solicita a los proveedores de prestaciones de servicios de salud con los cuales se tiene contrato vigente, el reporte de los datos reelacionados con este indicador respecto a los asegurados de Positiva que registran atenciones de este servicio en el periodo evaluado. | S18: Ninguna | T18: Supervisor y/o interventoria designada. | U18: 316 | V18: IPS | W18: 316 | X18: REPS HABILITADO
A19: calidad | B19: Oportunidad | C19: Tiempo promedio de espera para la asignación de cita de Nefrología | D19: Apartir de suscripcion del acuerdo del indicador con el prestador | E19: N/A | F19: I.C.53 | G19: Expresa el tiempo de espera en dias calendario que transcurren entre la fecha de solicitud de la cita para la consulta por Nefrología de primera vez y la fecha en la cual el usuario la solicitó | H19: Sumatoria de la diferencia de los dias calendario entre la fecha en la que se asignó la cita de Nefrología de primera vez y la fecha en la cual el usuario la solicitó / número total de citas de nefrología de primera vez asignadas | I19: Sumatoria de la diferencia de dias calendario entre la fecha en la que se asignó la cita de nefrología de primera vez y la fecha en la cual el usuario la solicitó | J19: Sistema de Gestión de Calidad de la Institución | K19: Número total de citas de nefrología de primera vez asignadas | L19: Sistema de Gestión de Calidad de la Institución | M19: Días | N19: 5 días calendario | O19: Trimestral | P19: Descendente | Q19: La consulta de primera vez hace referencia a la primera consulta del paciente que se registra por primera vez en el año, razón por la cual se excluye la consulta de control. Aplica para IPS y no aplica para los servicios de transporte especial de pacientes | R19: La firma de interventoria o supervisor solicita a los proveedores de prestaciones de servicios de salud con los cuales se tiene contrato vigente, el reporte de los datos reelacionados con este indicador respecto a los asegurados de Positiva que registran atenciones de este servicio en el periodo evaluado. | S19: Ninguna | T19: Supervisor y/o interventoria designada. | U19: 330 | V19: IPS | W19: 330 | X19: REPS HABILITADO
A20: calidad | B20: Oportunidad | C20: Tiempo promedio de espera para la asignación de cita de Nutrición y dietetica | D20: Apartir de suscripcion del acuerdo del indicador con el prestador | E20: N/A | F20: I.C.54 | G20: Expresa el tiempo de espera en dias calendario que transcurren entre la fecha de solicitud de la cita para la consulta por Nutrición y dietetica de primera vez y la fecha en la cual el usuario la solicitó | H20: Sumatoria de la diferencia de los dias calendario entre la fecha en la que se asignó la cita de nutrición y dietetica de primera vez y la fecha en la cual el usuario la solicitó / número total de citas de nutrición y dietetica a de primera vez asignadas | I20: Sumatoria de la diferencia de dias calendario entre la fecha en la que se asignó la cita de nutrición y dietetica de primera vez y la fecha en la cual el usuario la solicitó | J20: Sistema de Gestión de Calidad de la Institución | K20: Número total de citas de nutrición y dietetica de primera vez asignadas | L20: Sistema de Gestión de Calidad de la Institución | M20: Días | N20: 5 días calendario | O20: Trimestral | P20: Descendente | Q20: La consulta de primera vez hace referencia a la primera consulta del paciente que se registra por primera vez en el año, razón por la cual se excluye la consulta de control. Aplica para IPS y no aplica para los servicios de transporte especial de pacientes | R20: La firma de interventoria o supervisor solicita a los proveedores de prestaciones de servicios de salud con los cuales se tiene contrato vigente, el reporte de los datos reelacionados con este indicador respecto a los asegurados de Positiva que registran atenciones de este servicio en el periodo evaluado. | S20: Ninguna | T20: Supervisor y/o interventoria designada. | U20: 333 | V20: IPS | W20: 333 | X20: REPS HABILITADO
A21: calidad | B21: Oportunidad | C21: Tiempo promedio de espera para la asignación de cita de psicología | D21: Apartir de suscripcion del acuerdo del indicador con el prestador | E21: N/A | F21: I.C.55 | G21: Expresa el tiempo de espera en dias calendario que transcurren entre la fecha de solicitud de la cita para la consulta por psicologia de primera vez y la fecha en la cual el usuario la solicitó | H21: Sumatoria de la diferencia de los dias calendario entre la fecha en la que se asignó la cita de psicología de primera vez y la fecha en la cual el usuario la solicitó / número total de citas de psicología de primera vez asignadas | I21: Sumatoria de la diferencia de dias calendario entre la fecha en la que se asignó la cita de psicología de primera vez y la fecha en la cual el usuario la solicitó | J21: Sistema de Gestión de Calidad de la Institución | K21: Número total de citas de psicología de primera vez asignadas | L21: Sistema de Gestión de Calidad de la Institución | M21: Días | N21: 5 días calendario | O21: Trimestral | P21: Descendente | Q21: La consulta de primera vez hace referencia a la primera consulta del paciente que se registra por primera vez en el año, razón por la cual se excluye la consulta de control. Aplica para IPS y no aplica para los servicios de transporte especial de pacientes | R21: La firma de interventoria o supervisor solicita a los proveedores de prestaciones de servicios de salud con los cuales se tiene contrato vigente, el reporte de los datos reelacionados con este indicador respecto a los asegurados de Positiva que registran atenciones de este servicio en el periodo evaluado. | S21: Ninguna | T21: Supervisor y/o interventoria designada. | U21: 344 | V21: IPS | W21: 344 | X21: REPS HABILITADO
... A74: calidad | B74: Oportunidad | C74: Tiempo promedio de espera para la atención del paciente clasificado como Triage 2 en servicio de urgencias | D74: Apartir de suscripcion del acuerdo del indicador con el prestador | E74: P.3.10 | F74: I.C.108 | G74: Expresa el tiempo de espera en minutos para el paciente clasificado como Triage 2 en el servicio de urgencias hasta que se inicia la atención en consulta de urgencias por médico | H74: Sumatoria del número de minutos transcurridos a partir de que el paciente es clasificado como Triage 2 y el momento en el cual es atendido en consulta de Urgencias por médico/Número total de pacientes clasificados como Triage 2 | I74: Sumatoria del número de minutos transcurridos a partir de que el paciente es clasificado como Triage 2 y el momento en el cual es atendido en consulta de Urgencias por médico | J74: Reporte remitido por los prestadores de servicios de acuerdo a lo establecido por la Resolución 256 de 2016 | K74: Número total de pacientes clasificados como Triage 2 | L74: Reporte remitido por los prestadores de servicios de acuerdo a lo establecido por la Resolución 256 de 2016 | M74: Minutos | N74: 30 mínutos | O74: Trimestral | P74: Descendente | Q74: Sólo se tiene en cuenta el triage 2, es decir se excluyen los demás Triage. Aplica para IPS y no aplica para los servicios de transporte especial de pacientes | R74: La firma de interventoria solicita a los proveedores de prestaciones de servicios de salud con los cuales se tiene contrato vigente, copia del reporte de indicadores de calidad de acuerdo a la Resolución 256 de 2016 | S74: Se excluyen los Triage I, III, IV y V. | T74: Supervisor y/o interventoria designada. | U74: 1102 | V74: IPS | W74: 1102 | X74: REPS HABILITADO
A75: Calidad | B75: Satisfaccion | C75: Proporción de satisfacción global de los usuarios en la IPS | D75: Apartir de suscripcion del acuerdo del indicador con el prestador | E75: P.3.14 | F75: I.C.109 | G75: Expresa la proporción de usuarios sastisfechos con los servicios recibidos en la IPS | H75: Se calcula como el cociente entre el número de usuarios que respondieron "muy buena" o "buena" a la pregunta Cómo calificaría su experiencia global respecto a los servicios de salud que ha recibido a través de su IPS?, y el número de usuarios que respondieron la pregunta por 100 expresado como porcentaje | I75: Número de usuarios que respondieron "muy buena" o "buena" a la pregunta Cómo calificaría su experiencia global respecto a los servicios de salud que ha recibido a través de su IPS | J75: Reporte remitido por los prestadores de servicios de acuerdo a lo establecido por la Resolución 256 de 2016 | K75: Número de usuarios que respondieron la pregunta | L75: Reporte remitido por los prestadores de servicios de acuerdo a lo establecido por la Resolución 256 de 2016 | M75: Porcentaje | N75: 0.95 | O75: Trimestral | P75: Ascendente | Q75: Las opciones de respuesta del usuario a la pregunta Cómo calificaría su experiencia global respecto a los servicios de salud que ha recibido a través de su IPS ?, serian: 1= muy mala 2=mala, 3=regular, 4=Buena, 5=muy buena, 0=no informa. Aplica para la IPS y para los servicios de transporte espcial de pacientes | R75: El prestador remitirá los datos del indicador objeto de medición dentro de los treinta (30) días calendario siguientes a la terminación del respectivo trimestre. | S75: Se excluyen de la medición los usuarios que respondieron la pregunta Cómo calificaría su experiencia global respecto a los servicios de salud que ha recibido a través de su IPS ?: 0=no informa. | T75: Supervisor y/o interventoria designada. | U75: Todos los REPS | V75: IPS-RHI-RIESGO BIOLOGICO | W75: ALL | X75: TODOS
A76: Resultados en salud | B76: PQRD | C76: PQRD procedentes para el asegurado | D76: Apartir de suscripcion del acuerdo del indicador con el prestador | E76: N/A | F76: I.C.116 | G76: Monitorear las PQRD procedentes para los asegurados que permiten identificar inconformidades con el servicio | H76: PQRD o Tutelas procedentes a cargo del proveedor en el periodo | I76: PQRD o tutelas procedentes a cargo del proveedor en el periodo | J76: Reporte PQRD y tutelas grupo GISAT del periodo evaluado | K76: N/A | L76: N/A | M76: Número de PQRD procedente para el asegurado | N76: 0 | O76: Trimestral | P76: Descendente | Q76: Ninguna | R76: *El proveedor tiene el compromiso de apoyar la respuesta de las PQRD que le sean escaladas máximo dentro de los plazos contractualmente establecidos. *Las PQRD que no cuenten con apoyo de respuesta se tomarán como procedentes. | S76: Ninguna | T76: Supervisor y/o interventoria designada. | U76: Todos los REPS | V76: TODOS LOS PROVEEDORES | W76: ALL | X76: TODOS
A77: Gestión | B77: Oportunidad | C77: Oportunidad en la entrega de material de osteosíntesis | D77: Apartir de suscripcion del acuerdo del indicador con el prestador | E77: N/A | F77: I.C.118 | G77: Medir la oportunidad en el suminisitro del material de osteosintesis para los asegurados de la compañía. | H77: Número de autorizaciones entregadas completas según compromiso adquirido en tiempo por el proveedor *100 Número total de autorizaciones asignadas al proveedor. | I77: Número de autorizaciones entregadas completas según compromiso adquirido en tiempo por el proveedor *100 | J77: Soportes de las remisiones con fecha- hora -firma de recibido por parte de la IPS | K77: Número total de autorizaciones asignadas al proveedor. | L77: Reporte de autorizaciones de la herramienta tecnologica designada por la compañía. | M77: Porcentaje | N77: 0.98 | O77: Trimestral | P77: Ascendente | Q77: *La oportunidad de la entrega se validará de acuerdo a los tiempos definidos y compromiso de entrega. *El proveedor entregará el 100% de los soportes de las remisiones con fecha- hora -firma de recibido por parte de la IPS atendidos en el periodo evaluado. | R77: Muestra: Se realizara la validacion del 100% de la autorizaciones asignadas en el periodo a evaluar. Metodología denominador: 1.Se revisará en la herramienta tecnologíca todas las autorizaciones asignadas al proveedor. 2.Se excluiran de la medicion las autorizaciones que cumplan con los criterios definidos como exclusión. Metodología numerador: 1. Se revisará en la herramienta tecnologíca que todas las autorizaciones cuenten con lo definido en el indicador(Observaciones) segun aplique. | S77: • Situación especial que genere un impedimento de entrega oportuna del material correspondiente, con evidencia de reporte. • Autorización anulada, siempre y cuando el motivo de la anulación no sea por inoportunidad de entrega del material. • Autorización Anulada por vencimiento. • Médico/IPS, no aceptan el material entregado por el proveedor. (calidad del material) • Proveedor entrega el material, sin embargo, no es utilizado en el procedimiento quirúrgico. • Pendiente programación de cirugía. • Motivos de fuerza mayor. (mediante reporte mensual definiendo los criterios de no cumplimiento) • En los casos donde el médico cirujano ordene material de osteosíntesis adicional al autorizado posterior a la entrega por parte del proveedor de lo autorizado inicialmente | T77: Supervisor y/o interventoria designada. | U77: OEM06 | V77: MATERIAL DE OSTEOSINTESIS | W77: POR TIPO | X77: MATERIAL DE OSTEOSINTESIS
A78: Gestión | B78: Oportunidad | C78: Autorizaciones anuladas por no disponibilidad del material | D78: Apartir de suscripcion del acuerdo del indicador con el prestador | E78: N/A | F78: I.C.121 | G78: Medir las fallas y reprocesamiento del servicio para los asegurados. | H78: Número de autorizaciones anuladas por no disponibilidad del material de osteosintesis | I78: Número de autorizaciones anuladas por no disponibilidad del material de osteosintesis | J78: Soportes de anulación de autorización es por no disponibilida Reporte de autorización es del Aplicativo Tecnológico designado por la compañía | K78: NA | L78: NA | M78: Número de autorizaciones anuladas por no disponibilidad del material de osteosintesis | N78: 1 | O78: Trimestral | P78: Descendente | Q78: No aplica. | R78: 1.Se realizara la validacion del 100% de la autorizaciones anuladas en el periodo a evaluar. 2.Se revisara la causal de anulación de acuerdo con lo registrado en la herramienta tecnologica. 3. Se identificaran los casos asociados a autorizaciones anuladas por no disponibilidad del material de osteosintesis y se aplicara la formula. | S78: *Anulación por no entrega o no disponibilidad de material a causa de desastres naturales. *Anulación por no entrega o no disponibilidad de material por Casos fortuitos y/o eventos de fuerza mayor. *Anulación por no entrega o no disponibilidad de material por Problemas de orden público. *Anulación por no entrega o no disponibilidad de material por Escasez de insumos por importación o materia prima escasa. *Anulación por no entrega o no disponibilidad de material por elemento no contratado dentro del portafolio de servicios. Para aplicación de una exclusión esta debe estar debidamente soportada por parte del proveedor, en caso de no contar con soportes no será tomado como exclusión. | T78: Supervisor y/o interventoria designada. | U78: AAM09 | V78: MATERIAL DE OSTEOSINTESIS | W78: POR TIPO | X78: MATERIAL DE OSTEOSINTESIS
A79: calidad | B79: Oportunidad | C79: Oportunidad de atención riesgo biologico | D79: Apartir de suscripcion del acuerdo del indicador con el prestador | E79: N/A | F79: I.C.125 | G79: Medir la oportuna gestion del proveedor para los asegurados de la compañía con el objetivo de dar inicio en la atención | H79: Número de casos contactados dentro de las 24 horas siguientes a la generación de la autorización paquete riesgo biológico evidenciado en el aplicativo cuida 2/ N° total de casos asignados al proveedor de riesgo biológico por el aplicativo Positiva Cuida 2 con generación paquete riesgo biológico | I79: Número de casos contactados dentro de las 24 horas siguientes a la generación de la autorización paquete riesgo biológico evidenciado en el aplicativo cuida 2.0 | J79: Aplicativo Positiva CUIDA 2/ consulta integral/ bitácora publica/gestión de autorizaciones | K79: N° total de casos asignados al proveedor de riesgo biológico por el aplicativo Positiva Cuida 2.0 con generación paquete riesgo biológico | L79: Aplicativo Positiva CUIDA 2/ consulta integral/ bitácora publica/gestión de autorizaciones | M79: Porcentaje | N79: 0.98 | O79: Trimestral | P79: Ascendente | Q79: • El seguimiento del 100% de los casos debe estar registrado en Positiva Cuida 2.0 • El proveedor solamente entrega medicamentos para Terapia antirretroviral e inmunológica | R79: 1.Se revisará en la herramienta tecnologíca todos los casos asignados al proveedor de riesgo biológico por el aplicativo Positiva Cuida 2.0 con generación paquete riesgo biológico 2.Se excluiran de la medicion las autorizaciones que cumplan con los criterios definidos como exclusión. 3. De acuerdo con los registrado en la herramienta tecnologica Cuida 2.0 se validaran el número de casos contactados dentro de las 24 horas siguientes a la generación de la autorización paquete riesgo biológico. 4. Se aplicara la formula definida. Nota2: Se entiende como"Número de casos contactados dentro de las 24 horas siguientes a la generación de la autorización paquete riesgo biológico evidenciado en el aplicativo cuida 2.0" a los pacientes que cuenten con: • Contacto inicial con el afiliado en las 24 horas siguientes al reporte del accidente o asignación del caso. • Valoración inicial, descripción del caso y definición de seguimiento a realizar. | S79: • Caso sin siniestro calificado. • Anulación de la autorización emitida para atención por paquete de riesgo biológico no atribuibles al proveedor. • tiempos prolongados en la captura de los casos asignados si se soportan daños o actualizaciones en el sistema de la ARL Positiva, fuente de información principal de los asegurados y gestión. • Los casos reasignados a otros proveedores serán excluidos siempre y cuando se soporte con la anulación del servicio(no atribuibles al proveedor). • Los asegurados que NO deseen ser atendidos por el proveedor deben ser retirados del total de las asignaciones autorizadas. | T79: Supervisor y/o interventoria designada. | U79: OTA10,420,712,731 | V79: RIESGO BIOLOGICO | W79: 901248158 | X79: 901248158
